2020-01-10 11:13:26,828 root INFO Dividing 5 between 0
2020-01-10 11:13:26,829 root ERROR Error running task
Traceback (most recent call last):
  File "task_with_error_handling_step4.py", line 26, in <module>
    main(args.n1,args.n2,args.output)
  File "task_with_error_handling_step4.py", line 10, in main
    result = number/other_number
ZeroDivisionError: division by zero
